Workbook

Sheet Resumo
A1: Projeto de atendimento a crianças neurodivergentes – Agenda dos atendimentos
A2: Células em azul são premissas (editáveis); o restante é calculado.
A4: Premissa | B4: Valor | C4: Observação
A5: Dias de atendimento por ano | B5: =Calendário!B16 -> 246 | C5: Ver aba Calendário
A6: Horário de funcionamento | B6: 07h–19h | C6: Seg–sex; almoço 12h–13h
A7: Formato das sessões | B7: 4 × 30 min | C7: Formato C: todas de 30 min, horários seguidos, 2h por visita
A8: Sessões de terapia por criança a cada 4 semanas | B8: 24 | C8: Decisão da gestora; xadrez, capoeira, oficinas, médicos e odonto são extras
A9: Sessões por visita | B9: 4 | C9: 3 ou 4 especialidades; modelo usa 4
A10: Visitas por criança a cada 4 semanas | B10: =B8/B9 -> 6 | C10: 24 ÷ 4
A11: Ciclo da agenda (dias úteis) | B11: 10 | C11: 2 semanas: cada criança vem 3 vezes a cada 10 dias úteis
A12: Visitas por criança por ciclo | B12: =B10*B11/20 -> 3 | C12: 3 visitas a cada 2 semanas = 6 a cada 4 semanas
A13: Blocos de visita por dia | B13: 60 | C13: Comprovado por solver: 60 visitas/dia cabem com horários seguidos e vagas das salas
A16: Cenários (formato C)
A17: Indicador | B17: Cenário 1: 100% de ocupação | C17: Cenário 2: 90% (10% reposição)
A18: Crianças por bloco de visita | B18: =B11/B12 -> 3.3333333 | C18: =INT(B11/B12) -> 3
A19: Crianças com pacote completo | B19: =ROUND(B13*B18,0) -> 200 | C19: =B13*C18 -> 180
A20: Visitas por dia | B20: =B19*B12/B11 -> 60 | C20: =C19*B12/B11 -> 54
A21: Blocos livres por dia (reposição) | B21: =B13-B20 -> 0 | C21: =B13-C20 -> 6
A22: Ocupação dos blocos | B22: =B20/B13 -> 1 | C22: =C20/B13 -> 0.9
A23: Sessões de 30 min por dia | B23: =B20*B9 -> 240 | C23: =C20*B9 -> 216
A24: Sessões de terapia por ano | B24: =B19*B8*B5/20 -> 59040 | C24: =C19*B8*B5/20 -> 53136
A25: Horário da criança | B25: 180 fixas + 20 com horário variável | C25: Fixo: mesmo horário, sala e ordem sempre
A27: Notas
A28: Cenário 2: cada bloco de 2h atende 3 crianças em rodízio e fica livre 1 vez a cada 10 dias úteis, no mesmo horário e com os mesmos profissionais (vaga de reposição).
A29: Cenário 1: as mesmas 180 crianças fixas + 20 crianças flexíveis (F01–F20), que ocupam as vagas livres do Cenário 2. O horário das flexíveis varia entre visitas e não sobra vaga para reposição.
A30: Tetos teóricos calculados antes da grade (225 e 202 crianças) não foram obtidos na grade real; 63 ou mais visitas por dia não foram comprovadas nem descartadas.
A31: Pacotes-modelo (aba Grade do dia) são ilustrativos; a composição real depende da triagem. Todos têm pelo menos 2 entre Psicologia, TO e Fono.
A32: Mês de 18 dias (fev/2027) entrega menos de 6 visitas no calendário; o ciclo de 10 dias úteis garante 24 sessões a cada 4 semanas.

Sheet Calendário
A1: Calendário de funcionamento – jul/2026 a jun/2027 (Aracaju/SE)
A3: Mês | B3: Dias de funcionamento | D3: Feriados descontados
A4: Jul/2026 | B4: 22 | D4: Data | E4: Dia | F4: Feriado
A5: Ago/2026 | B5: 21 | D5: 08/07/2026 | E5: Qua | F5: Emancipação Política de Sergipe (estadual)
A6: Set/2026 | B6: 21 | D6: 07/09/2026 | E6: Seg | F6: Independência (nacional)
A7: Out/2026 | B7: 21 | D7: 12/10/2026 | E7: Seg | F7: N. Sra. Aparecida (nacional)
A8: Nov/2026 | B8: 19 | D8: 02/11/2026 | E8: Seg | F8: Finados (nacional)
A9: Dez/2026 | B9: 21 | D9: 20/11/2026 | E9: Sex | F9: Consciência Negra (nacional)
A10: Jan/2027 | B10: 20 | D10: 08/12/2026 | E10: Ter | F10: N. Sra. da Conceição (municipal Aracaju) – conferir decreto
A11: Fev/2027 | B11: 18 | D11: 25/12/2026 | E11: Sex | F11: Natal (nacional)
A12: Mar/2027 | B12: 21 | D12: 01/01/2027 | E12: Sex | F12: Confraternização Universal (nacional)
A13: Abr/2027 | B13: 21 | D13: 08/02/2027 | E13: Seg | F13: Carnaval (ponto facultativo)
A14: Mai/2027 | B14: 20 | D14: 09/02/2027 | E14: Ter | F14: Carnaval (ponto facultativo)
A15: Jun/2027 | B15: =21+IF($B$19="S",1,0) -> 21 | D15: 17/03/2027 | E15: Qua | F15: Aniversário de Aracaju (municipal)
A16: Total no ano | B16: =SUM(B4:B15) -> 246 | D16: 26/03/2027 | E16: Sex | F16: Sexta-feira Santa (nacional)
D17: 21/04/2027 | E17: Qua | F17: Tiradentes (nacional)
A18: Base: 261 dias úteis seg–sex no período, menos 15 feriados em dia útil. Itens marcados 'conferir decreto' dependem do decreto oficial da Prefeitura. | D18: 27/05/2027 | E18: Qui | F18: Corpus Christi (confirmado: sem atendimento)
A19: São João (24/06/2027) funciona? (S/N) | B19: N | D19: 24/06/2027 | E19: Qui | F19: São João (municipal Aracaju) – EM ABERTO: ver célula B19
A20: Decisão em aberto: com 'N' o dia é descontado (246 dias); com 'S' o total passa para 247.

Sheet Grade do dia
A1: Grade do dia (igual de segunda a sexta) – 60 blocos de visita
A2: Cada célula mostra o bloco (B01…B60) que ocupa aquela vaga naquele horário. Cor = pacote-modelo.
A4: Horário | B4: Psicologia vaga 1 | C4: Psicologia vaga 2 | D4: Terapia Ocupacional vaga 1 | E4: Terapia Ocupacional vaga 2 | F4: Fonoaudiologia vaga 1 | G4: Fonoaudiologia vaga 2 | H4: Psicopedagogia vaga 1 | I4: Psicopedagogia vaga 2 | J4: Psicomotricidade vaga 1 | K4: Psicomotricidade vaga 2 | L4: Musicoterapia | M4: Terapia alimentar vaga 1 | N4: Terapia alimentar vaga 2
A5: 07:00–07:30 | B5: B01 | D5: B04 | F5: B02 | J5: B05 | K5: B06 | M5: B03
A6: 07:30–08:00 | B6: B02 | D6: B05 | E6: B08 | F6: B03 | G6: B06 | L6: B07 | M6: B01 | N6: B04
A7: 08:00–08:30 | B7: B09 | C7: B10 | D7: B06 | E7: B07 | F7: B04 | G7: B05 | H7: B01 | I7: B03 | J7: B12 | K7: B13 | L7: B11 | M7: B02 | N7: B08
A8: 08:30–09:00 | B8: B03 | C8: B13 | D8: B09 | E8: B11 | F8: B01 | G8: B07 | H8: B02 | I8: B10 | J8: B04 | K8: B08 | L8: B12 | M8: B05 | N8: B06
A9: 09:00–09:30 | B9: B12 | C9: B15 | D9: B10 | E9: B14 | F9: B08 | G9: B13 | H9: B07 | I9: B11 | J9: B09 | K9: B16
A10: 09:30–10:00 | B10: B14 | C10: B18 | F10: B11 | G10: B12 | H10: B09 | J10: B10 | K10: B15 | L10: B13 | M10: B16 | N10: B17
A11: 10:00–10:30 | B11: B21 | C11: B24 | D11: B16 | E11: B23 | F11: B17 | G11: B22 | H11: B14 | I11: B19 | J11: B20 | K11: B26 | L11: B15 | M11: B18 | N11: B25
A12: 10:30–11:00 | B12: B19 | C12: B22 | D12: B18 | E12: B20 | F12: B15 | G12: B16 | H12: B17 | I12: B23 | J12: B14 | K12: B25 | L12: B26 | M12: B21 | N12: B24
A13: 11:00–11:30 | B13: B17 | C13: B20 | D13: B19 | E13: B25 | F13: B21 | G13: B26 | H13: B22 | J13: B18 | K13: B24 | L13: B23
A14: 11:30–12:00 | B14: B25 | C14: B26 | D14: B24 | F14: B23 | H14: B20 | I14: B21 | J14: B19 | M14: B22
A15: Almoço
A16: 13:00–13:30 | B16: B31 | C16: B33 | D16: B27 | E16: B28 | H16: B29 | J16: B34 | L16: B30 | M16: B32
A17: 13:30–14:00 | B17: B27 | C17: B34 | D17: B32 | E17: B33 | F17: B29 | G17: B35 | H17: B30 | J17: B28 | K17: B31
A18: 14:00–14:30 | B18: B32 | C18: B37 | D18: B30 | E18: B31 | F18: B34 | H18: B28 | I18: B36 | J18: B27 | K18: B38 | L18: B29 | M18: B33 | N18: B35
A19: 14:30–15:00 | B19: B28 | C19: B38 | D19: B29 | E19: B36 | F19: B30 | G19: B39 | H19: B27 | I19: B35 | J19: B32 | K19: B33 | L19: B34 | M19: B31 | N19: B37
A20: 15:00–15:30 | B20: B35 | C20: B40 | D20: B37 | E20: B46 | F20: B43 | G20: B47 | H20: B39 | I20: B41 | J20: B36 | K20: B45 | L20: B44 | M20: B38 | N20: B42
A21: 15:30–16:00 | B21: B36 | C21: B42 | D21: B38 | E21: B41 | F21: B45 | G21: B46 | H21: B40 | I21: B43 | J21: B37 | K21: B44 | L21: B39 | M21: B47
A22: 16:00–16:30 | B22: B41 | C22: B44 | D22: B39 | E22: B43 | F22: B42 | G22: B49 | H22: B48 | J22: B40 | K22: B47 | L22: B45 | M22: B46
A23: 16:30–17:00 | B23: B45 | C23: B48 | D23: B40 | E23: B47 | F23: B44 | G23: B51 | H23: B42 | I23: B50 | J23: B41 | K23: B46 | L23: B43 | M23: B49
A24: 17:00–17:30 | B24: B49 | C24: B56 | D24: B48 | E24: B50 | F24: B52 | G24: B58 | H24: B51 | I24: B54 | J24: B57 | K24: B59 | L24: B55 | M24: B53 | N24: B60
A25: 17:30–18:00 | B25: B53 | C25: B58 | D25: B56 | E25: B59 | F25: B57 | G25: B60 | H25: B49 | I25: B55 | J25: B48 | K25: B50 | L25: B54 | M25: B51 | N25: B52
A26: 18:00–18:30 | B26: B50 | C26: B51 | D26: B54 | F26: B53 | G26: B55 | H26: B52 | J26: B58 | K26: B60 | L26: B57 | M26: B56 | N26: B59
A27: 18:30–19:00 | B27: B52 | C27: B57 | D27: B55 | E27: B60 | F27: B54 | G27: B59 | H27: B53 | J27: B56 | L27: B58
A29: Pacotes-modelo
A30: Pacote 1 | B30: Psicologia, Terapia Ocupacional, Psicopedagogia, Psicomotricidade | F30: 12 blocos/dia
A31: Pacote 2 | B31: Psicologia, Fonoaudiologia, Psicopedagogia, Terapia alimentar | F31: 12 blocos/dia
A32: Pacote 3 | B32: Terapia Ocupacional, Fonoaudiologia, Psicopedagogia, Musicoterapia | F32: 9 blocos/dia
A33: Pacote 4 | B33: Psicologia, Terapia Ocupacional, Psicomotricidade, Terapia alimentar | F33: 9 blocos/dia
A34: Pacote 5 | B34: Psicologia, Fonoaudiologia, Psicomotricidade, Musicoterapia | F34: 9 blocos/dia
A35: Pacote 6 | B35: Terapia Ocupacional, Fonoaudiologia, Psicomotricidade, Terapia alimentar | F35: 9 blocos/dia

Sheet Blocos
A1: Blocos de visita: horários e salas
A3: Bloco | B3: Pacote | C3: Início | D3: Fim | E3: 1ª sessão | F3: 2ª sessão | G3: 3ª sessão | H3: 4ª sessão
A4: B01 | B4: 2 | C4: 07:00 | D4: 09:00 | E4: 07:00 Psicologia | F4: 07:30 Terapia alimentar | G4: 08:00 Psicopedagogia | H4: 08:30 Fonoaudiologia
A5: B02 | B5: 2 | C5: 07:00 | D5: 09:00 | E5: 07:00 Fonoaudiologia | F5: 07:30 Psicologia | G5: 08:00 Terapia alimentar | H5: 08:30 Psicopedagogia
A6: B03 | B6: 2 | C6: 07:00 | D6: 09:00 | E6: 07:00 Terapia alimentar | F6: 07:30 Fonoaudiologia | G6: 08:00 Psicopedagogia | H6: 08:30 Psicologia
A7: B04 | B7: 6 | C7: 07:00 | D7: 09:00 | E7: 07:00 Terapia Ocupacional | F7: 07:30 Terapia alimentar | G7: 08:00 Fonoaudiologia | H7: 08:30 Psicomotricidade
A8: B05 | B8: 6 | C8: 07:00 | D8: 09:00 | E8: 07:00 Psicomotricidade | F8: 07:30 Terapia Ocupacional | G8: 08:00 Fonoaudiologia | H8: 08:30 Terapia alimentar
A9: B06 | B9: 6 | C9: 07:00 | D9: 09:00 | E9: 07:00 Psicomotricidade | F9: 07:30 Fonoaudiologia | G9: 08:00 Terapia Ocupacional | H9: 08:30 Terapia alimentar
A10: B07 | B10: 3 | C10: 07:30 | D10: 09:30 | E10: 07:30 Musicoterapia | F10: 08:00 Terapia Ocupacional | G10: 08:30 Fonoaudiologia | H10: 09:00 Psicopedagogia
A11: B08 | B11: 6 | C11: 07:30 | D11: 09:30 | E11: 07:30 Terapia Ocupacional | F11: 08:00 Terapia alimentar | G11: 08:30 Psicomotricidade | H11: 09:00 Fonoaudiologia
A12: B09 | B12: 1 | C12: 08:00 | D12: 10:00 | E12: 08:00 Psicologia | F12: 08:30 Terapia Ocupacional | G12: 09:00 Psicomotricidade | H12: 09:30 Psicopedagogia
A13: B10 | B13: 1 | C13: 08:00 | D13: 10:00 | E13: 08:00 Psicologia | F13: 08:30 Psicopedagogia | G13: 09:00 Terapia Ocupacional | H13: 09:30 Psicomotricidade
A14: B11 | B14: 3 | C14: 08:00 | D14: 10:00 | E14: 08:00 Musicoterapia | F14: 08:30 Terapia Ocupacional | G14: 09:00 Psicopedagogia | H14: 09:30 Fonoaudiologia
A15: B12 | B15: 5 | C15: 08:00 | D15: 10:00 | E15: 08:00 Psicomotricidade | F15: 08:30 Musicoterapia | G15: 09:00 Psicologia | H15: 09:30 Fonoaudiologia
... A63: B60 | B63: 6 | C63: 17:00 | D63: 19:00 | E63: 17:00 Terapia alimentar | F63: 17:30 Fonoaudiologia | G63: 18:00 Psicomotricidade | H63: 18:30 Terapia Ocupacional

Sheet Ciclo Cenário 2
A1: Cenário 2: quem ocupa cada bloco em cada dia do ciclo (10 dias úteis)
A2: Cada criança (C001–C180) vem 3 vezes por ciclo, sempre no mesmo bloco. 'livre' = vaga de reposição daquele horário. Trocar C### pelo nome real.
A4: Bloco | B4: Início | C4: Pacote | D4: Seg S1 | E4: Ter S1 | F4: Qua S1 | G4: Qui S1 | H4: Sex S1 | I4: Seg S2 | J4: Ter S2 | K4: Qua S2 | L4: Qui S2 | M4: Sex S2
A5: B01 | B5: 07:00 | C5: 2 | D5: livre | E5: C001 | F5: C002 | G5: C003 | H5: C001 | I5: C002 | J5: C003 | K5: C001 | L5: C002 | M5: C003
A6: B02 | B6: 07:00 | C6: 2 | D6: C004 | E6: C005 | F6: C006 | G6: C004 | H6: C005 | I6: C006 | J6: livre | K6: C004 | L6: C005 | M6: C006
A7: B03 | B7: 07:00 | C7: 2 | D7: C009 | E7: livre | F7: C007 | G7: C008 | H7: C009 | I7: C007 | J7: C008 | K7: C009 | L7: C007 | M7: C008
A8: B04 | B8: 07:00 | C8: 6 | D8: livre | E8: C010 | F8: C011 | G8: C012 | H8: C010 | I8: C011 | J8: C012 | K8: C010 | L8: C011 | M8: C012
A9: B05 | B9: 07:00 | C9: 6 | D9: C014 | E9: C015 | F9: C013 | G9: C014 | H9: C015 | I9: C013 | J9: C014 | K9: C015 | L9: livre | M9: C013
A10: B06 | B10: 07:00 | C10: 6 | D10: C017 | E10: C018 | F10: C016 | G10: C017 | H10: C018 | I10: livre | J10: C016 | K10: C017 | L10: C018 | M10: C016
A11: B07 | B11: 07:30 | C11: 3 | D11: livre | E11: C019 | F11: C020 | G11: C021 | H11: C019 | I11: C020 | J11: C021 | K11: C019 | L11: C020 | M11: C021
A12: B08 | B12: 07:30 | C12: 6 | D12: C022 | E12: C023 | F12: C024 | G12: livre | H12: C022 | I12: C023 | J12: C024 | K12: C022 | L12: C023 | M12: C024
A13: B09 | B13: 08:00 | C13: 1 | D13: livre | E13: C025 | F13: C026 | G13: C027 | H13: C025 | I13: C026 | J13: C027 | K13: C025 | L13: C026 | M13: C027
A14: B10 | B14: 08:00 | C14: 1 | D14: C028 | E14: C029 | F14: C030 | G14: C028 | H14: C029 | I14: C030 | J14: livre | K14: C028 | L14: C029 | M14: C030
A15: B11 | B15: 08:00 | C15: 3 | D15: C032 | E15: C033 | F15: C031 | G15: C032 | H15: C033 | I15: C031 | J15: C032 | K15: C033 | L15: livre | M15: C031
A16: B12 | B16: 08:00 | C16: 5 | D16: livre | E16: C034 | F16: C035 | G16: C036 | H16: C034 | I16: C035 | J16: C036 | K16: C034 | L16: C035 | M16: C036
... A64: B60 | B64: 17:00 | C64: 6 | D64: C179 | E64: C180 | F64: livre | G64: C178 | H64: C179 | I64: C180 | J64: C178 | K64: C179 | L64: C180 | M64: C178

Sheet Ciclo Cenário 1
A1: Cenário 1: ocupação de 100%. Quem ocupa cada bloco em cada dia do ciclo (10 dias úteis)
A2: C001–C180: crianças fixas (mesmo horário sempre). F01–F20: crianças flexíveis, que ocupam as vagas que no Cenário 2 ficam livres para reposição.
A4: Bloco | B4: Início | C4: Pacote | D4: Seg S1 | E4: Ter S1 | F4: Qua S1 | G4: Qui S1 | H4: Sex S1 | I4: Seg S2 | J4: Ter S2 | K4: Qua S2 | L4: Qui S2 | M4: Sex S2
A5: B01 | B5: 07:00 | C5: 2 | D5: F05 | E5: C001 | F5: C002 | G5: C003 | H5: C001 | I5: C002 | J5: C003 | K5: C001 | L5: C002 | M5: C003
A6: B02 | B6: 07:00 | C6: 2 | D6: C004 | E6: C005 | F6: C006 | G6: C004 | H6: C005 | I6: C006 | J6: F07 | K6: C004 | L6: C005 | M6: C006
A7: B03 | B7: 07:00 | C7: 2 | D7: C009 | E7: F06 | F7: C007 | G7: C008 | H7: C009 | I7: C007 | J7: C008 | K7: C009 | L7: C007 | M7: C008
A8: B04 | B8: 07:00 | C8: 6 | D8: F18 | E8: C010 | F8: C011 | G8: C012 | H8: C010 | I8: C011 | J8: C012 | K8: C010 | L8: C011 | M8: C012
A9: B05 | B9: 07:00 | C9: 6 | D9: C014 | E9: C015 | F9: C013 | G9: C014 | H9: C015 | I9: C013 | J9: C014 | K9: C015 | L9: F19 | M9: C013
A10: B06 | B10: 07:00 | C10: 6 | D10: C017 | E10: C018 | F10: C016 | G10: C017 | H10: C018 | I10: F20 | J10: C016 | K10: C017 | L10: C018 | M10: C016
A11: B07 | B11: 07:30 | C11: 3 | D11: F11 | E11: C019 | F11: C020 | G11: C021 | H11: C019 | I11: C020 | J11: C021 | K11: C019 | L11: C020 | M11: C021
A12: B08 | B12: 07:30 | C12: 6 | D12: C022 | E12: C023 | F12: C024 | G12: F18 | H12: C022 | I12: C023 | J12: C024 | K12: C022 | L12: C023 | M12: C024
A13: B09 | B13: 08:00 | C13: 1 | D13: F01 | E13: C025 | F13: C026 | G13: C027 | H13: C025 | I13: C026 | J13: C027 | K13: C025 | L13: C026 | M13: C027
A14: B10 | B14: 08:00 | C14: 1 | D14: C028 | E14: C029 | F14: C030 | G14: C028 | H14: C029 | I14: C030 | J14: F01 | K14: C028 | L14: C029 | M14: C030
A15: B11 | B15: 08:00 | C15: 3 | D15: C032 | E15: C033 | F15: C031 | G15: C032 | H15: C033 | I15: C031 | J15: C032 | K15: C033 | L15: F09 | M15: C031
A16: B12 | B16: 08:00 | C16: 5 | D16: F15 | E16: C034 | F16: C035 | G16: C036 | H16: C034 | I16: C035 | J16: C036 | K16: C034 | L16: C035 | M16: C036
... A64: B60 | B64: 17:00 | C64: 6 | D64: C179 | E64: C180 | F64: F20 | G64: C178 | H64: C179 | I64: C180 | J64: C178 | K64: C179 | L64: C180 | M64: C178

Sheet Crianças
A1: Lista de vagas de criança (substituir o código pelo nome)
A3: Código | B3: Tipo | C3: Cenários | D3: Pacote | E3: Dias do ciclo | F3: Bloco e horário
A4: C001 | B4: Fixa | C4: 1 e 2 | D4: 2 | E4: Ter S1, Sex S1, Qua S2 | F4: B01, 07:00–09:00
A5: C002 | B5: Fixa | C5: 1 e 2 | D5: 2 | E5: Qua S1, Seg S2, Qui S2 | F5: B01, 07:00–09:00
A6: C003 | B6: Fixa | C6: 1 e 2 | D6: 2 | E6: Qui S1, Ter S2, Sex S2 | F6: B01, 07:00–09:00
A7: C004 | B7: Fixa | C7: 1 e 2 | D7: 2 | E7: Seg S1, Qui S1, Qua S2 | F7: B02, 07:00–09:00
A8: C005 | B8: Fixa | C8: 1 e 2 | D8: 2 | E8: Ter S1, Sex S1, Qui S2 | F8: B02, 07:00–09:00
A9: C006 | B9: Fixa | C9: 1 e 2 | D9: 2 | E9: Qua S1, Seg S2, Sex S2 | F9: B02, 07:00–09:00
A10: C007 | B10: Fixa | C10: 1 e 2 | D10: 2 | E10: Qua S1, Seg S2, Qui S2 | F10: B03, 07:00–09:00
A11: C008 | B11: Fixa | C11: 1 e 2 | D11: 2 | E11: Qui S1, Ter S2, Sex S2 | F11: B03, 07:00–09:00
A12: C009 | B12: Fixa | C12: 1 e 2 | D12: 2 | E12: Seg S1, Sex S1, Qua S2 | F12: B03, 07:00–09:00
A13: C010 | B13: Fixa | C13: 1 e 2 | D13: 6 | E13: Ter S1, Sex S1, Qua S2 | F13: B04, 07:00–09:00
A14: C011 | B14: Fixa | C14: 1 e 2 | D14: 6 | E14: Qua S1, Seg S2, Qui S2 | F14: B04, 07:00–09:00
A15: C012 | B15: Fixa | C15: 1 e 2 | D15: 6 | E15: Qui S1, Ter S2, Sex S2 | F15: B04, 07:00–09:00
... A203: F20 | B203: Flexível | C203: 1 | D203: 6 | E203: Qua S1, Seg S2, Sex S2 | F203: Qua S1 B60 17:00–19:00; Seg S2 B06 07:00–09:00; Sex S2 B46 15:00–17:00

Sheet Serviços extras
A1: Serviços extras e de apoio
A3: Atendimento médico (1 dia por mês por especialidade; consultas de 30 min; 08h–12h e 13h–17h = 16 consultas/dia). Datas sugeridas.
A4: Mês | B4: Neuropediatra | C4: Psiquiatra infantil | D4: Pediatra
A5: 07/2026 | B5: 14/07 (ter) | C5: 15/07 (qua) | D5: 23/07 (qui)
A6: 08/2026 | B6: 11/08 (ter) | C6: 19/08 (qua) | D6: 27/08 (qui)
A7: 09/2026 | B7: 08/09 (ter) | C7: 16/09 (qua) | D7: 24/09 (qui)
A8: 10/2026 | B8: 13/10 (ter) | C8: 21/10 (qua) | D8: 22/10 (qui)
A9: 11/2026 | B9: 10/11 (ter) | C9: 18/11 (qua) | D9: 26/11 (qui)
A10: 12/2026 | B10: 09/12 (qua) | C10: 16/12 (qua) | D10: 24/12 (qui)
A11: 01/2027 | B11: 12/01 (ter) | C11: 20/01 (qua) | D11: 28/01 (qui)
A12: 02/2027 | B12: 10/02 (qua) | C12: 17/02 (qua) | D12: 25/02 (qui)
A13: 03/2027 | B13: 09/03 (ter) | C13: 18/03 (qui) | D13: 25/03 (qui)
A14: 04/2027 | B14: 13/04 (ter) | C14: 22/04 (qui) | D14: 22/04 (qui)
A15: 05/2027 | B15: 11/05 (ter) | C15: 19/05 (qua) | D15: 28/05 (sex)
A16: 06/2027 | B16: 08/06 (ter) | C16: 16/06 (qua) | D16: 25/06 (sex)
A17: Capacidade: 16 consultas × 12 dias = 192 por médico por ano.
A19: Odontologia: 1 dentista por dia, consultas de 40 min = 16 vagas/dia (7 de manhã, 9 à tarde)
A20: Manhã | B20: Tarde
A21: 07:00–07:40 | B21: 13:00–13:40
A22: 07:40–08:20 | B22: 13:40–14:20
A23: 08:20–09:00 | B23: 14:20–15:00
A24: 09:00–09:40 | B24: 15:00–15:40
A25: 09:40–10:20 | B25: 15:40–16:20
A26: 10:20–11:00 | B26: 16:20–17:00
A27: 11:00–11:40 | B27: 17:00–17:40
B28: 17:40–18:20
B29: 18:20–19:00
A31: Psicóloga dos pais: sessões de 30 min; G = grupo (até 8 pais), I = individual
A32: Horário | B32: Tipo | C32: Horário | D32: Tipo
A33: 07:00–07:30 | B33: I | C33: 13:30–14:00 | D33: I
A34: 07:30–08:00 | B34: I | C34: 14:00–14:30 | D34: I
A35: 08:00–08:30 | B35: I | C35: 14:30–15:00 | D35: G
A36: 08:30–09:00 | B36: G | C36: 15:00–15:30 | D36: I
A37: 09:00–09:30 | B37: I | C37: 15:30–16:00 | D37: I
A38: 09:30–10:00 | B38: I | C38: 16:00–16:30 | D38: I
A39: 10:00–10:30 | B39: I | C39: 16:30–17:00 | D39: G
A40: 10:30–11:00 | B40: G | C40: 17:00–17:30 | D40: I
A41: 11:00–11:30 | B41: I | C41: 17:30–18:00 | D41: I
A42: 11:30–12:00 | B42: I | C42: 18:00–18:30 | D42: I
A43: 13:00–13:30 | B43: I | C43: 18:30–19:00 | D43: I
...

Sheet Equipe e turnos
A1: Equipe e turnos (remuneração por turno: manhã 07h–12h e tarde 13h–19h)
A3: Função | B3: Profissionais por turno | C3: Turnos por dia | D3: Dias por ano | E3: Turnos por ano
A4: Fonoaudiologia | B4: 2 | C4: 2 | D4: =Calendário!$B$16 -> 246 | E4: =B4*C4*D4 -> 984
A5: Terapia Ocupacional | B5: 2 | C5: 2 | D5: =Calendário!$B$16 -> 246 | E5: =B5*C5*D5 -> 984
A6: Psicologia | B6: 2 | C6: 2 | D6: =Calendário!$B$16 -> 246 | E6: =B6*C6*D6 -> 984
A7: Psicopedagogia | B7: 2 | C7: 2 | D7: =Calendário!$B$16 -> 246 | E7: =B7*C7*D7 -> 984
A8: Psicomotricidade | B8: 2 | C8: 2 | D8: =Calendário!$B$16 -> 246 | E8: =B8*C8*D8 -> 984
A9: Musicoterapia | B9: 1 | C9: 2 | D9: =Calendário!$B$16 -> 246 | E9: =B9*C9*D9 -> 492
A10: Terapia alimentar (nutrição) | B10: 1 | C10: 2 | D10: =Calendário!$B$16 -> 246 | E10: =B10*C10*D10 -> 492
A11: Psicóloga dos pais | B11: 1 | C11: 2 | D11: =Calendário!$B$16 -> 246 | E11: =B11*C11*D11 -> 492
A12: Odontologia (1 por dia) | B12: 1 | C12: 2 | D12: =Calendário!$B$16 -> 246 | E12: =B12*C12*D12 -> 492
A13: Capoeira (1 por vez) | B13: 1 | C13: 2 | D13: =Calendário!$B$16 -> 246 | E13: =B13*C13*D13 -> 492
A14: Xadrez (1 por turno) | B14: 1 | C14: 2 | D14: =Calendário!$B$16 -> 246 | E14: =B14*C14*D14 -> 492
A15: Médicos (3 especialidades, 1 dia/mês, 2 turnos) | B15: 3 | C15: 2 | D15: 12 | E15: =B15*C15*D15 -> 72
A16: Total de turnos por ano | E16: =SUM(E4:E15) -> 7944
A18: Xadrez: 1 profissional por turno (2 por dia). Capoeira: 1 profissional por turno (confirmado).
A19: Dentista: pode ser profissionais diferentes por dia; o custo anual considera 1 por turno em todos os dias de atendimento.
